Workbook

Sheet Léeme
A1: Inventario de contratos · Bloque 1 de la solicitud SFSP v0.2
A3: Corte de lectura | B3: Red 5550. bloque 241.307 · 2026-09-22
A4: Cómo se obtuvo | B4: Lectura directa del nodo público rpc.ordenglobal-rpc.com (Besu 26.7.1), sólo consultas: eth_call, eth_getCode, eth_getStorageAt, recibos y trazas. No se firmó ni se movió nada.
A5: Contratos en la 5550 | B5: 172. Coincide con los 172 contratos con código que registró el constructor del génesis. Se recorrió la cadena entera: 241.307 bloques, 95 transacciones, 0 despliegues de contratos (directos o internos).
A6: Por qué todos son del bloque 0 | B6: La 5550 actual arrancó el 25-ago-2026 (bloque 1: 23:40:15 UTC) con un génesis que copió código y almacenamiento de la cadena anterior. Ningún contrato se desplegó después. Fuente: infra/migracion-cadena/reinicio-5550/ETAPA-3-EL-CORTE.md; el hash del bloque 0 del nodo (0x56b3cf56…) coincide con el del acta.
A7: Tenedores | B7: Se preguntó el saldo de 465 direcciones conocidas (código, datos de la migración, eventos). Si la suma de saldos iguala el supply total, la lista está COMPLETA y la concentración es exacta. Para AUKA, ONDK, HARV y USDK se leyeron además, por su huella en el almacenamiento, los saldos de direcciones que no están en el repositorio.
A8: NO DISPONIBLE | B8: Casilla en amarillo: el dato no se puede obtener de la cadena ni del repositorio. No se estimó nada.
A9: Columnas extra | B9: Casillas en gris-azul a la derecha de las pedidas: hechos que ayudan a clasificar (huella del bytecode, duplicados, funciones privilegiadas presentes, cobertura de tenedores).
A10: La cadena 8532 | B10: No respondió el 22-sep (23.23.205.33:80, conexión rechazada). La hoja 1.2 sale del volcado completo del estado al corte (genesis-id/datos/cadena-8532.json, origen s3://ordenglobal-cadena-8532-respaldo/2026-08-10) emparejado con la 5550 dirección por dirección y, donde faltaba la dirección, por su huella keccak.
A11: Alertas | B11: Ver la hoja «Alertas»: hallazgos que afectan el diseño de la migración.

Sheet 1.1 Contratos 5550
A1: Dirección del contrato | B1: Nombre | C1: Símbolo | D1: Estándar | E1: Decimales | F1: Supply total | G1: Supply circulante | H1: Bloque de despliegue | I1: Fecha de despliegue | J1: Cuenta desplegadora | K1: Roles privilegiados | L1: Número de tenedores | M1: Concentración (top 10) | N1: Última transferencia | O1: Código verificado | P1: Contratos relacionados | Q1: Responsable interno | R1: Origen | S1: Suma top 10 (unidades) | T1: Cobertura de tenedores | U1: Supply sin ubicar (unidades) | V1: En poder de la cuenta desplegadora (unidades) | W1: Funciones privilegiadas en el bytecode | X1: Contratos con el mismo bytecode | Y1: SHA-256 del bytecode | Z1: Huella registrada en ORDENSCAN | AA1: Indicios (hechos, no clasificación) | AB1: Alerta
A2: 0x37bcb1c800220e414ed09e044becd3bf9d06ea67 | B2: SILVER KAPITAL | C2: AGKA | D2: ERC-20 | E2: 18 | F2: 100000000 | G2: NO DISPONIBLE: falta la lista oficial de billeteras de tesorería y control interno (ver columnas extra) | H2: 0 | I2: 2026-08-25 (génesis de la 5550; bloque 1 a las 23:40:15 UTC). Despliegue original en la 8532: NO DISPONIBLE | J2: Ninguna en la 5550 (sembrado en el génesis). En la 8532: NO DISPONIBLE | K2: Sin dueño legible por owner(); sin funciones privilegiadas detectadas | L2: 1 | M2: =S2/F2 -> 1 | N2: Ninguna desde el génesis (25-ago-2026). Historial en la 8532: NO DISPONIBLE | O2: No. El repositorio no tiene la fuente Solidity; ver «Huella registrada en ORDENSCAN» | P2: — | Q2: NO DISPONIBLE | R2: NO DISPONIBLE | S2: 100000000 | T2: 1 | W2: — | X2: 8 | Y2: 29ed4635fa24b53b59a7f91f97ed36923b32907ef0e79c244f6eceaea6eae85c | Z2: No | AA2: el símbolo AGKA aparece en 2 contratos; bytecode idéntico a otros 8 | AB2: —
A3: 0x961f798f998c7ff44d47d62c7fa1b572ef187a4b | B3: AGKA Token | C3: AGKA | D3: ERC-20 | E3: 18 | F3: 500000000 | G3: NO DISPONIBLE: falta la lista oficial de billeteras de tesorería y control interno (ver columnas extra) | H3: 0 | I3: 2026-08-25 (génesis de la 5550; bloque 1 a las 23:40:15 UTC). Despliegue original en la 8532: NO DISPONIBLE | J3: Ninguna en la 5550 (sembrado en el génesis). En la 8532: NO DISPONIBLE | K3: Sin dueño legible por owner(); funciones presentes: mint · quién puede llamarlas: NO DISPONIBLE (sin fuente) | L3: 3 | M3: =S3/F3 -> 1 | N3: 2026-09-12 15:41 UTC | O3: No. El repositorio no tiene la fuente Solidity; ver «Huella registrada en ORDENSCAN» | P3: — | Q3: NO DISPONIBLE | R3: NO DISPONIBLE | S3: 500000000 | T3: 1 | W3: mint | X3: 3 | Y3: 35cd1e6484dd9d021001e7cf57a3d4bb71a5f894f7089c0b56dcc8b41d870d0d | Z3: Sí | AA3: en el catálogo de ORDENSCAN; el símbolo AGKA aparece en 2 contratos; bytecode idéntico a otros 3 | AB3: —
A4: 0x2a31ba919a5339fcb0f8aeeffce2c807b16007fe | B4: AGROTECH | C4: AGRO | D4: ERC-20 | E4: 18 | F4: 33000000 | G4: NO DISPONIBLE: falta la lista oficial de billeteras de tesorería y control interno (ver columnas extra) | H4: 0 | I4: 2026-08-25 (génesis de la 5550; bloque 1 a las 23:40:15 UTC). Despliegue original en la 8532: NO DISPONIBLE | J4: Ninguna en la 5550 (sembrado en el génesis). En la 8532: NO DISPONIBLE | K4: Sin dueño legible por owner(); sin funciones privilegiadas detectadas | L4: 3 | M4: =S4/F4 -> 1 | N4: Ninguna desde el génesis (25-ago-2026). Historial en la 8532: NO DISPONIBLE | O4: No. El repositorio no tiene la fuente Solidity; ver «Huella registrada en ORDENSCAN» | P4: en 4 par(es)/pool(s) AMM | Q4: NO DISPONIBLE | R4: NO DISPONIBLE | S4: 33000000 | T4: 1 | W4: — | X4: 8 | Y4: 29ed4635fa24b53b59a7f91f97ed36923b32907ef0e79c244f6eceaea6eae85c | Z4: Sí | AA4: en el catálogo de ORDENSCAN; bytecode idéntico a otros 8 | AB4: —
A5: 0xae14db486872ac07d74ad69cc09590239b21ba2e | B5: ARTIFICIAL INTELLIGENCE | C5: AIT | D5: ERC-20 | E5: 18 | F5: 21000000 | G5: NO DISPONIBLE: falta la lista oficial de billeteras de tesorería y control interno (ver columnas extra) | H5: 0 | I5: 2026-08-25 (génesis de la 5550; bloque 1 a las 23:40:15 UTC). Despliegue original en la 8532: NO DISPONIBLE | J5: Ninguna en la 5550 (sembrado en el génesis). En la 8532: NO DISPONIBLE | K5: Sin dueño legible por owner(); sin funciones privilegiadas detectadas | L5: 3 | M5: =S5/F5 -> 1 | N5: Ninguna desde el génesis (25-ago-2026). Historial en la 8532: NO DISPONIBLE | O5: No. El repositorio no tiene la fuente Solidity; ver «Huella registrada en ORDENSCAN» | P5: en 2 par(es)/pool(s) AMM | Q5: NO DISPONIBLE | R5: NO DISPONIBLE | S5: 21000000 | T5: 1 | W5: — | X5: 8 | Y5: 29ed4635fa24b53b59a7f91f97ed36923b32907ef0e79c244f6eceaea6eae85c | Z5: Sí | AA5: en el catálogo de ORDENSCAN; bytecode idéntico a otros 8 | AB5: —
A6: 0x69846ac960d45f9946c613dfce1b761d37faf098 | B6: ATHLETIC | C6: ASL | D6: ERC-20 | E6: 18 | F6: 77000000 | G6: NO DISPONIBLE: falta la lista oficial de billeteras de tesorería y control interno (ver columnas extra) | H6: 0 | I6: 2026-08-25 (génesis de la 5550; bloque 1 a las 23:40:15 UTC). Despliegue original en la 8532: NO DISPONIBLE | J6: Ninguna en la 5550 (sembrado en el génesis). En la 8532: NO DISPONIBLE | K6: Sin dueño legible por owner(); sin funciones privilegiadas detectadas | L6: 3 | M6: =S6/F6 -> 1 | N6: Ninguna desde el génesis (25-ago-2026). Historial en la 8532: NO DISPONIBLE | O6: No. El repositorio no tiene la fuente Solidity; ver «Huella registrada en ORDENSCAN» | P6: en 2 par(es)/pool(s) AMM | Q6: NO DISPONIBLE | R6: NO DISPONIBLE | S6: 77000000 | T6: 1 | W6: — | X6: 8 | Y6: 29ed4635fa24b53b59a7f91f97ed36923b32907ef0e79c244f6eceaea6eae85c | Z6: Sí | AA6: en el catálogo de ORDENSCAN; bytecode idéntico a otros 8 | AB6: —
A7: 0xb58382be75879732f4abe96100f1b7faa6b4ce63 | B7: AUBEX | C7: AUBEX | D7: ERC-20 | E7: 18 | F7: 1e+26 | G7: NO DISPONIBLE: falta la lista oficial de billeteras de tesorería y control interno (ver columnas extra) | H7: 0 | I7: 2026-08-25 (génesis de la 5550; bloque 1 a las 23:40:15 UTC). Despliegue original en la 8532: NO DISPONIBLE | J7: Ninguna en la 5550 (sembrado en el génesis). En la 8532: NO DISPONIBLE | K7: Sin dueño legible por owner(); sin funciones privilegiadas detectadas | L7: 1 | M7: =S7/F7 -> 1 | N7: Ninguna desde el génesis (25-ago-2026). Historial en la 8532: NO DISPONIBLE | O7: No. El repositorio no tiene la fuente Solidity; ver «Huella registrada en ORDENSCAN» | P7: — | Q7: NO DISPONIBLE | R7: NO DISPONIBLE | S7: 1e+26 | T7: 1 | V7: 1e+26 | W7: — | X7: 0 | Y7: 3cea58dfcc42bd20004f8c59e4a2b1d770371582724c4aba2affeaf89de72fce | Z7: No | AA7: el símbolo AUBEX aparece en 2 contratos | AB7: —
A8: 0xf1498640b27a66c0dc505093d70911c060e04fb0 | B8: AUBEX | C8: AUBEX | D8: ERC-20 | E8: 18 | F8: 100000000 | G8: NO DISPONIBLE: falta la lista oficial de billeteras de tesorería y control interno (ver columnas extra) | H8: 0 | I8: 2026-08-25 (génesis de la 5550; bloque 1 a las 23:40:15 UTC). Despliegue original en la 8532: NO DISPONIBLE | J8: Ninguna en la 5550 (sembrado en el génesis). En la 8532: NO DISPONIBLE | K8: Sin dueño legible por owner(); sin funciones privilegiadas detectadas | L8: 3 | M8: =S8/F8 -> 1 | N8: 2026-09-17 23:33 UTC | O8: No. El repositorio no tiene la fuente Solidity; ver «Huella registrada en ORDENSCAN» | P8: — | Q8: NO DISPONIBLE | R8: NO DISPONIBLE | S8: 100000000 | T8: 1 | W8: — | X8: 0 | Y8: c96730055fb1f35b490c8d4a882f67016226a85822bc43dbfb06a339a573c598 | Z8: Sí | AA8: en el catálogo de ORDENSCAN; el símbolo AUBEX aparece en 2 contratos | AB8: —
A9: 0x6facc8df79cedc6c5065442ce27e915aa3a26b9b | B9: Gold Kapital | C9: AUKA | D9: ERC-20 | E9: 18 | F9: 55000000 | G9: NO DISPONIBLE: falta la lista oficial de billeteras de tesorería y control interno (ver columnas extra) | H9: 0 | I9: 2026-08-25 (génesis de la 5550; bloque 1 a las 23:40:15 UTC). Despliegue original en la 8532: NO DISPONIBLE | J9: Ninguna en la 5550 (sembrado en el génesis). En la 8532: NO DISPONIBLE | K9: Sin dueño legible por owner(); funciones presentes: mint · quién puede llamarlas: NO DISPONIBLE (sin fuente) | L9: 28 con dirección conocida + hasta 7 entradas sin dirección (pueden incluir autorizaciones) | M9: =S9/F9 -> 0.99982122 | N9: 2026-09-21 23:35 UTC | O9: No. El repositorio no tiene la fuente Solidity; ver «Huella registrada en ORDENSCAN» | P9: en 10 par(es)/pool(s) AMM | Q9: NO DISPONIBLE | R9: NO DISPONIBLE | S9: 54990167 | T9: 0.9998214 | U9: 9823.01 | W9: mint | X9: 3 | Y9: 35cd1e6484dd9d021001e7cf57a3d4bb71a5f894f7089c0b56dcc8b41d870d0d | Z9: Sí | AA9: en el catálogo de ORDENSCAN; bytecode idéntico a otros 3 | AB9: —
A10: 0x15ff8678517249a82bb57da095b7fa2ac73c8d0c | B10: Coffee | C10: COFFEE | D10: ERC-20 | E10: 18 | F10: 0 | G10: NO DISPONIBLE: falta la lista oficial de billeteras de tesorería y control interno (ver columnas extra) | H10: 0 | I10: 2026-08-25 (génesis de la 5550; bloque 1 a las 23:40:15 UTC). Despliegue original en la 8532: NO DISPONIBLE | J10: Ninguna en la 5550 (sembrado en el génesis). En la 8532: NO DISPONIBLE | K10: owner(): 0xa07a2ba9735568b989378bbb3b1439ee9c5e5714 | L10: 0 | M10: NO DISPONIBLE | N10: Ninguna desde el génesis (25-ago-2026). Historial en la 8532: NO DISPONIBLE | O10: No. El repositorio no tiene la fuente Solidity; ver «Huella registrada en ORDENSCAN» | P10: — | Q10: NO DISPONIBLE | R10: NO DISPONIBLE | S10: 0 | W10: mint, transferOwnership, renounceOwnership | X10: 4 | Y10: f1a374da96493b2348f670782e3476a5e13d31d104e14b98c43dda0411c43c72 | Z10: No | AA10: el símbolo COFFEE aparece en 5 contratos; bytecode idéntico a otros 4 | AB10: —
A11: 0x30b5af871facf490bd1811f58d2f62dc7b4da2d5 | B11: Coffee | C11: COFFEE | D11: ERC-20 | E11: 18 | F11: 0 | G11: NO DISPONIBLE: falta la lista oficial de billeteras de tesorería y control interno (ver columnas extra) | H11: 0 | I11: 2026-08-25 (génesis de la 5550; bloque 1 a las 23:40:15 UTC). Despliegue original en la 8532: NO DISPONIBLE | J11: Ninguna en la 5550 (sembrado en el génesis). En la 8532: NO DISPONIBLE | K11: owner(): 0xa07a2ba9735568b989378bbb3b1439ee9c5e5714 | L11: 0 | M11: NO DISPONIBLE | N11: Ninguna desde el génesis (25-ago-2026). Historial en la 8532: NO DISPONIBLE | O11: No. El repositorio no tiene la fuente Solidity; ver «Huella registrada en ORDENSCAN» | P11: — | Q11: NO DISPONIBLE | R11: NO DISPONIBLE | S11: 0 | W11: mint, transferOwnership, renounceOwnership | X11: 4 | Y11: f1a374da96493b2348f670782e3476a5e13d31d104e14b98c43dda0411c43c72 | Z11: No | AA11: el símbolo COFFEE aparece en 5 contratos; bytecode idéntico a otros 4 | AB11: —
A12: 0x69027e07a4d410f1913c35f23fa4fcb32c8079d6 | B12: Coffee | C12: COFFEE | D12: ERC-20 | E12: 18 | F12: 0 | G12: NO DISPONIBLE: falta la lista oficial de billeteras de tesorería y control interno (ver columnas extra) | H12: 0 | I12: 2026-08-25 (génesis de la 5550; bloque 1 a las 23:40:15 UTC). Despliegue original en la 8532: NO DISPONIBLE | J12: Ninguna en la 5550 (sembrado en el génesis). En la 8532: NO DISPONIBLE | K12: owner(): 0xa07a2ba9735568b989378bbb3b1439ee9c5e5714 | L12: 0 | M12: NO DISPONIBLE | N12: Ninguna desde el génesis (25-ago-2026). Historial en la 8532: NO DISPONIBLE | O12: No. El repositorio no tiene la fuente Solidity; ver «Huella registrada en ORDENSCAN» | P12: — | Q12: NO DISPONIBLE | R12: NO DISPONIBLE | S12: 0 | W12: mint, transferOwnership, renounceOwnership | X12: 4 | Y12: f1a374da96493b2348f670782e3476a5e13d31d104e14b98c43dda0411c43c72 | Z12: No | AA12: el símbolo COFFEE aparece en 5 contratos; bytecode idéntico a otros 4 | AB12: —
A13: 0xd9d7b43a0d536ad33207ff289407cf5f94e0cda0 | B13: Coffee | C13: COFFEE | D13: ERC-20 | E13: 18 | F13: 0 | G13: NO DISPONIBLE: falta la lista oficial de billeteras de tesorería y control interno (ver columnas extra) | H13: 0 | I13: 2026-08-25 (génesis de la 5550; bloque 1 a las 23:40:15 UTC). Despliegue original en la 8532: NO DISPONIBLE | J13: Ninguna en la 5550 (sembrado en el génesis). En la 8532: NO DISPONIBLE | K13: owner(): 0xee3e8e7eb0b5823d225fe19be2c3f11c47460591 | L13: 0 | M13: NO DISPONIBLE | N13: Ninguna desde el génesis (25-ago-2026). Historial en la 8532: NO DISPONIBLE | O13: No. El repositorio no tiene la fuente Solidity; ver «Huella registrada en ORDENSCAN» | P13: — | Q13: NO DISPONIBLE | R13: NO DISPONIBLE | S13: 0 | W13: mint, transferOwnership, renounceOwnership | X13: 4 | Y13: f1a374da96493b2348f670782e3476a5e13d31d104e14b98c43dda0411c43c72 | Z13: No | AA13: el símbolo COFFEE aparece en 5 contratos; bytecode idéntico a otros 4 | AB13: —
A14: 0xf59d64bdbfeb65ca67c07b050ce590ecb297ab54 | B14: Coffee | C14: COFFEE | D14: ERC-20 | E14: 18 | F14: 0 | G14: NO DISPONIBLE: falta la lista oficial de billeteras de tesorería y control interno (ver columnas extra) | H14: 0 | I14: 2026-08-25 (génesis de la 5550; bloque 1 a las 23:40:15 UTC). Despliegue original en la 8532: NO DISPONIBLE | J14: Ninguna en la 5550 (sembrado en el génesis). En la 8532: NO DISPONIBLE | K14: owner(): 0xa07a2ba9735568b989378bbb3b1439ee9c5e5714 | L14: 0 | M14: NO DISPONIBLE | N14: Ninguna desde el génesis (25-ago-2026). Historial en la 8532: NO DISPONIBLE | O14: No. El repositorio no tiene la fuente Solidity; ver «Huella registrada en ORDENSCAN» | P14: — | Q14: NO DISPONIBLE | R14: NO DISPONIBLE | S14: 0 | W14: mint, transferOwnership, renounceOwnership | X14: 4 | Y14: f1a374da96493b2348f670782e3476a5e13d31d104e14b98c43dda0411c43c72 | Z14: No | AA14: el símbolo COFFEE aparece en 5 contratos; bytecode idéntico a otros 4 | AB14: —
A15: 0x0fa04d11f28b28cbc9b98dd016f02023addb1923 | B15: Harvi | C15: HARV | D15: ERC-20 | E15: 18 | F15: 1000000000000 | G15: NO DISPONIBLE: falta la lista oficial de billeteras de tesorería y control interno (ver columnas extra) | H15: 0 | I15: 2026-08-25 (génesis de la 5550; bloque 1 a las 23:40:15 UTC). Despliegue original en la 8532: NO DISPONIBLE | J15: Ninguna en la 5550 (sembrado en el génesis). En la 8532: NO DISPONIBLE | K15: Sin dueño legible por owner(); funciones presentes: mint, burn · quién puede llamarlas: NO DISPONIBLE (sin fuente) | L15: 4 (exacto; 1 sin dirección conocida, leídos por huella) | M15: =S15/F15 -> 1 | N15: Ninguna desde el génesis (25-ago-2026). Historial en la 8532: NO DISPONIBLE | O15: No. El repositorio no tiene la fuente Solidity; ver «Huella registrada en ORDENSCAN» | P15: — | Q15: NO DISPONIBLE | R15: NO DISPONIBLE | S15: 1000000000000 | T15: 1 | W15: mint, burn | X15: 2 | Y15: 640abb699107fa0d25a6b0275b82b572aaea2427c7dcdc3ac0c9a745d1320402 | Z15: Sí | AA15: en el catálogo de ORDENSCAN; el símbolo HARV aparece en 15 contratos; bytecode idéntico a otros 2 | AB15: —
A16: 0x14c27762b115cb4e6d4c8fec69577590795db3b0 | B16: HARVI | C16: HARV | D16: ERC-20 | E16: 18 | F16: 1e+30 | G16: NO DISPONIBLE: falta la lista oficial de billeteras de tesorería y control interno (ver columnas extra) | H16: 0 | I16: 2026-08-25 (génesis de la 5550; bloque 1 a las 23:40:15 UTC). Despliegue original en la 8532: NO DISPONIBLE | J16: Ninguna en la 5550 (sembrado en el génesis). En la 8532: NO DISPONIBLE | K16: Sin dueño legible por owner(); sin funciones privilegiadas detectadas | L16: 1 | M16: =S16/F16 -> 1 | N16: Ninguna desde el génesis (25-ago-2026). Historial en la 8532: NO DISPONIBLE | O16: No. El repositorio no tiene la fuente Solidity; ver «Huella registrada en ORDENSCAN» | P16: — | Q16: NO DISPONIBLE | R16: NO DISPONIBLE | S16: 1e+30 | T16: 1 | V16: 1e+30 | W16: — | X16: 13 | Y16: 327070a3cb2b28d44930ffceaf30f350f4ccf36f14d6dddca8dafce73c50caf0 | Z16: No | AA16: el símbolo HARV aparece en 15 contratos; bytecode idéntico a otros 13 | AB16: —
A17: 0x362dc3f596cfd606c000ad12c81e74afbf1e2ddc | B17: HARVI | C17: HARV | D17: ERC-20 | E17: 18 | F17: 1e+30 | G17: NO DISPONIBLE: falta la lista oficial de billeteras de tesorería y control interno (ver columnas extra) | H17: 0 | I17: 2026-08-25 (génesis de la 5550; bloque 1 a las 23:40:15 UTC). Despliegue original en la 8532: NO DISPONIBLE | J17: Ninguna en la 5550 (sembrado en el génesis). En la 8532: NO DISPONIBLE | K17: Sin dueño legible por owner(); sin funciones privilegiadas detectadas | L17: 1 | M17: =S17/F17 -> 1 | N17: Ninguna desde el génesis (25-ago-2026). Historial en la 8532: NO DISPONIBLE | O17: No. El repositorio no tiene la fuente Solidity; ver «Huella registrada en ORDENSCAN» | P17: — | Q17: NO DISPONIBLE | R17: NO DISPONIBLE | S17: 1e+30 | T17: 1 | V17: 1e+30 | W17: — | X17: 13 | Y17: 327070a3cb2b28d44930ffceaf30f350f4ccf36f14d6dddca8dafce73c50caf0 | Z17: No | AA17: el símbolo HARV aparece en 15 contratos; bytecode idéntico a otros 13 | AB17: —
A18: 0x3f20f56e5a54fedafe7243e7702ff9019adca2ad | B18: HARVI | C18: HARV | D18: ERC-20 | E18: 18 | F18: 1e+30 | G18: NO DISPONIBLE: falta la lista oficial de billeteras de tesorería y control interno (ver columnas extra) | H18: 0 | I18: 2026-08-25 (génesis de la 5550; bloque 1 a las 23:40:15 UTC). Despliegue original en la 8532: NO DISPONIBLE | J18: Ninguna en la 5550 (sembrado en el génesis). En la 8532: NO DISPONIBLE | K18: Sin dueño legible por owner(); sin funciones privilegiadas detectadas | L18: 1 | M18: =S18/F18 -> 1 | N18: Ninguna desde el génesis (25-ago-2026). Historial en la 8532: NO DISPONIBLE | O18: No. El repositorio no tiene la fuente Solidity; ver «Huella registrada en ORDENSCAN» | P18: — | Q18: NO DISPONIBLE | R18: NO DISPONIBLE | S18: 1e+30 | T18: 1 | V18: 1e+30 | W18: — | X18: 13 | Y18: 327070a3cb2b28d44930ffceaf30f350f4ccf36f14d6dddca8dafce73c50caf0 | Z18: No | AA18: el símbolo HARV aparece en 15 contratos; bytecode idéntico a otros 13 | AB18: —
A19: 0x4b2e05dd7a20fe11edbc9f4b606b48fe5b48c4a0 | B19: HARVI | C19: HARV | D19: ERC-20 | E19: 18 | F19: 1e+26 | G19: NO DISPONIBLE: falta la lista oficial de billeteras de tesorería y control interno (ver columnas extra) | H19: 0 | I19: 2026-08-25 (génesis de la 5550; bloque 1 a las 23:40:15 UTC). Despliegue original en la 8532: NO DISPONIBLE | J19: Ninguna en la 5550 (sembrado en el génesis). En la 8532: NO DISPONIBLE | K19: Sin dueño legible por owner(); sin funciones privilegiadas detectadas | L19: 1 | M19: =S19/F19 -> 1 | N19: Ninguna desde el génesis (25-ago-2026). Historial en la 8532: NO DISPONIBLE | O19: No. El repositorio no tiene la fuente Solidity; ver «Huella registrada en ORDENSCAN» | P19: — | Q19: NO DISPONIBLE | R19: NO DISPONIBLE | S19: 1e+26 | T19: 1 | V19: 1e+26 | W19: — | X19: 13 | Y19: 327070a3cb2b28d44930ffceaf30f350f4ccf36f14d6dddca8dafce73c50caf0 | Z19: No | AA19: el símbolo HARV aparece en 15 contratos; bytecode idéntico a otros 13 | AB19: —
A20: 0x6efd4ea7b21dae976194cbcb1b823b32da6ec595 | B20: HARVI | C20: HARV | D20: ERC-20 | E20: 18 | F20: 1e+30 | G20: NO DISPONIBLE: falta la lista oficial de billeteras de tesorería y control interno (ver columnas extra) | H20: 0 | I20: 2026-08-25 (génesis de la 5550; bloque 1 a las 23:40:15 UTC). Despliegue original en la 8532: NO DISPONIBLE | J20: Ninguna en la 5550 (sembrado en el génesis). En la 8532: NO DISPONIBLE | K20: Sin dueño legible por owner(); sin funciones privilegiadas detectadas | L20: 1 | M20: =S20/F20 -> 1 | N20: Ninguna desde el génesis (25-ago-2026). Historial en la 8532: NO DISPONIBLE | O20: No. El repositorio no tiene la fuente Solidity; ver «Huella registrada en ORDENSCAN» | P20: — | Q20: NO DISPONIBLE | R20: NO DISPONIBLE | S20: 1e+30 | T20: 1 | V20: 1e+30 | W20: — | X20: 13 | Y20: 327070a3cb2b28d44930ffceaf30f350f4ccf36f14d6dddca8dafce73c50caf0 | Z20: No | AA20: el símbolo HARV aparece en 15 contratos; bytecode idéntico a otros 13 | AB20: —
A21: 0x7047ae3f30eb5249ca4a50e18fcdfcaf9294d3db | B21: HARVI | C21: HARV | D21: ERC-20 | E21: 18 | F21: 1e+27 | G21: NO DISPONIBLE: falta la lista oficial de billeteras de tesorería y control interno (ver columnas extra) | H21: 0 | I21: 2026-08-25 (génesis de la 5550; bloque 1 a las 23:40:15 UTC). Despliegue original en la 8532: NO DISPONIBLE | J21: Ninguna en la 5550 (sembrado en el génesis). En la 8532: NO DISPONIBLE | K21: Sin dueño legible por owner(); sin funciones privilegiadas detectadas | L21: 1 | M21: =S21/F21 -> 1 | N21: Ninguna desde el génesis (25-ago-2026). Historial en la 8532: NO DISPONIBLE | O21: No. El repositorio no tiene la fuente Solidity; ver «Huella registrada en ORDENSCAN» | P21: — | Q21: NO DISPONIBLE | R21: NO DISPONIBLE | S21: 1e+27 | T21: 1 | V21: 1e+27 | W21: — | X21: 13 | Y21: 327070a3cb2b28d44930ffceaf30f350f4ccf36f14d6dddca8dafce73c50caf0 | Z21: No | AA21: el símbolo HARV aparece en 15 contratos; bytecode idéntico a otros 13 | AB21: —
A22: 0x8df67373dfb952d5c029235cade8382404241686 | B22: HARVI | C22: HARV | D22: ERC-20 | E22: 18 | F22: 1e+30 | G22: NO DISPONIBLE: falta la lista oficial de billeteras de tesorería y control interno (ver columnas extra) | H22: 0 | I22: 2026-08-25 (génesis de la 5550; bloque 1 a las 23:40:15 UTC). Despliegue original en la 8532: NO DISPONIBLE | J22: Ninguna en la 5550 (sembrado en el génesis). En la 8532: NO DISPONIBLE | K22: Sin dueño legible por owner(); sin funciones privilegiadas detectadas | L22: 1 | M22: =S22/F22 -> 1 | N22: Ninguna desde el génesis (25-ago-2026). Historial en la 8532: NO DISPONIBLE | O22: No. El repositorio no tiene la fuente Solidity; ver «Huella registrada en ORDENSCAN» | P22: — | Q22: NO DISPONIBLE | R22: NO DISPONIBLE | S22: 1e+30 | T22: 1 | V22: 1e+30 | W22: — | X22: 13 | Y22: 327070a3cb2b28d44930ffceaf30f350f4ccf36f14d6dddca8dafce73c50caf0 | Z22: No | AA22: el símbolo HARV aparece en 15 contratos; bytecode idéntico a otros 13 | AB22: —
A23: 0x9a8652c0a043320c28d8d6e40c964bf719ac6278 | B23: HARVI | C23: HARV | D23: ERC-20 | E23: 18 | F23: 1e+30 | G23: NO DISPONIBLE: falta la lista oficial de billeteras de tesorería y control interno (ver columnas extra) | H23: 0 | I23: 2026-08-25 (génesis de la 5550; bloque 1 a las 23:40:15 UTC). Despliegue original en la 8532: NO DISPONIBLE | J23: Ninguna en la 5550 (sembrado en el génesis). En la 8532: NO DISPONIBLE | K23: Sin dueño legible por owner(); sin funciones privilegiadas detectadas | L23: 1 | M23: =S23/F23 -> 1 | N23: Ninguna desde el génesis (25-ago-2026). Historial en la 8532: NO DISPONIBLE | O23: No. El repositorio no tiene la fuente Solidity; ver «Huella registrada en ORDENSCAN» | P23: — | Q23: NO DISPONIBLE | R23: NO DISPONIBLE | S23: 1e+30 | T23: 1 | V23: 1e+30 | W23: — | X23: 13 | Y23: 327070a3cb2b28d44930ffceaf30f350f4ccf36f14d6dddca8dafce73c50caf0 | Z23: No | AA23: el símbolo HARV aparece en 15 contratos; bytecode idéntico a otros 13 | AB23: —
A24: 0xafb7955e0702a472c30def61c37ebad194d8897b | B24: HARVI | C24: HARV | D24: ERC-20 | E24: 18 | F24: 1e+26 | G24: NO DISPONIBLE: falta la lista oficial de billeteras de tesorería y control interno (ver columnas extra) | H24: 0 | I24: 2026-08-25 (génesis de la 5550; bloque 1 a las 23:40:15 UTC). Despliegue original en la 8532: NO DISPONIBLE | J24: Ninguna en la 5550 (sembrado en el génesis). En la 8532: NO DISPONIBLE | K24: Sin dueño legible por owner(); sin funciones privilegiadas detectadas | L24: 1 | M24: =S24/F24 -> 1 | N24: Ninguna desde el génesis (25-ago-2026). Historial en la 8532: NO DISPONIBLE | O24: No. El repositorio no tiene la fuente Solidity; ver «Huella registrada en ORDENSCAN» | P24: — | Q24: NO DISPONIBLE | R24: NO DISPONIBLE | S24: 1e+26 | T24: 1 | V24: 1e+26 | W24: — | X24: 13 | Y24: 327070a3cb2b28d44930ffceaf30f350f4ccf36f14d6dddca8dafce73c50caf0 | Z24: No | AA24: el símbolo HARV aparece en 15 contratos; bytecode idéntico a otros 13 | AB24: —
A25: 0xb1d0990c5def34608832f21418f865575fc3889d | B25: Harvi | C25: HARV | D25: ERC-20 | E25: 18 | F25: 1000000000000 | G25: NO DISPONIBLE: falta la lista oficial de billeteras de tesorería y control interno (ver columnas extra) | H25: 0 | I25: 2026-08-25 (génesis de la 5550; bloque 1 a las 23:40:15 UTC). Despliegue original en la 8532: NO DISPONIBLE | J25: Ninguna en la 5550 (sembrado en el génesis). En la 8532: NO DISPONIBLE | K25: Sin dueño legible por owner(); funciones presentes: mint, burn · quién puede llamarlas: NO DISPONIBLE (sin fuente) | L25: 1 | M25: =S25/F25 -> 1 | N25: Ninguna desde el génesis (25-ago-2026). Historial en la 8532: NO DISPONIBLE | O25: No. El repositorio no tiene la fuente Solidity; ver «Huella registrada en ORDENSCAN» | P25: — | Q25: NO DISPONIBLE | R25: NO DISPONIBLE | S25: 1000000000000 | T25: 1 | W25: mint, burn | X25: 2 | Y25: 640abb699107fa0d25a6b0275b82b572aaea2427c7dcdc3ac0c9a745d1320402 | Z25: No | AA25: el símbolo HARV aparece en 15 contratos; bytecode idéntico a otros 2 | AB25: —
A26: 0xb364447c938668e7b88d8d5bd3a2526874ac7ddf | B26: HARVI | C26: HARV | D26: ERC-20 | E26: 18 | F26: 1e+30 | G26: NO DISPONIBLE: falta la lista oficial de billeteras de tesorería y control interno (ver columnas extra) | H26: 0 | I26: 2026-08-25 (génesis de la 5550; bloque 1 a las 23:40:15 UTC). Despliegue original en la 8532: NO DISPONIBLE | J26: Ninguna en la 5550 (sembrado en el génesis). En la 8532: NO DISPONIBLE | K26: Sin dueño legible por owner(); sin funciones privilegiadas detectadas | L26: 1 | M26: =S26/F26 -> 1 | N26: Ninguna desde el génesis (25-ago-2026). Historial en la 8532: NO DISPONIBLE | O26: No. El repositorio no tiene la fuente Solidity; ver «Huella registrada en ORDENSCAN» | P26: — | Q26: NO DISPONIBLE | R26: NO DISPONIBLE | S26: 1e+30 | T26: 1 | V26: 1e+30 | W26: — | X26: 13 | Y26: 327070a3cb2b28d44930ffceaf30f350f4ccf36f14d6dddca8dafce73c50caf0 | Z26: No | AA26: el símbolo HARV aparece en 15 contratos; bytecode idéntico a otros 13 | AB26: —
A27: 0xc8a8b43490c27662ef524e0d3d8c68f7da8b79a4 | B27: HARVI | C27: HARV | D27: ERC-20 | E27: 18 | F27: 1e+30 | G27: NO DISPONIBLE: falta la lista oficial de billeteras de tesorería y control interno (ver columnas extra) | H27: 0 | I27: 2026-08-25 (génesis de la 5550; bloque 1 a las 23:40:15 UTC). Despliegue original en la 8532: NO DISPONIBLE | J27: Ninguna en la 5550 (sembrado en el génesis). En la 8532: NO DISPONIBLE | K27: Sin dueño legible por owner(); sin funciones privilegiadas detectadas | L27: 1 | M27: =S27/F27 -> 1 | N27: Ninguna desde el génesis (25-ago-2026). Historial en la 8532: NO DISPONIBLE | O27: No. El repositorio no tiene la fuente Solidity; ver «Huella registrada en ORDENSCAN» | P27: — | Q27: NO DISPONIBLE | R27: NO DISPONIBLE | S27: 1e+30 | T27: 1 | V27: 1e+30 | W27: — | X27: 13 | Y27: 327070a3cb2b28d44930ffceaf30f350f4ccf36f14d6dddca8dafce73c50caf0 | Z27: No | AA27: el símbolo HARV aparece en 15 contratos; bytecode idéntico a otros 13 | AB27: —
A28: 0xddf4de2722772891f1e783499362e9147d660c38 | B28: HARVI | C28: HARV | D28: ERC-20 | E28: 18 | F28: 1e+26 | G28: NO DISPONIBLE: falta la lista oficial de billeteras de tesorería y control interno (ver columnas extra) | H28: 0 | I28: 2026-08-25 (génesis de la 5550; bloque 1 a las 23:40:15 UTC). Despliegue original en la 8532: NO DISPONIBLE | J28: Ninguna en la 5550 (sembrado en el génesis). En la 8532: NO DISPONIBLE | K28: Sin dueño legible por owner(); sin funciones privilegiadas detectadas | L28: 1 | M28: =S28/F28 -> 1 | N28: Ninguna desde el génesis (25-ago-2026). Historial en la 8532: NO DISPONIBLE | O28: No. El repositorio no tiene la fuente Solidity; ver «Huella registrada en ORDENSCAN» | P28: — | Q28: NO DISPONIBLE | R28: NO DISPONIBLE | S28: 1e+26 | T28: 1 | V28: 1e+26 | W28: — | X28: 13 | Y28: 327070a3cb2b28d44930ffceaf30f350f4ccf36f14d6dddca8dafce73c50caf0 | Z28: No | AA28: el símbolo HARV aparece en 15 contratos; bytecode idéntico a otros 13 | AB28: —
A29: 0xf3b27382bcc5177c7832172dfc2d070f19d9c752 | B29: HARVI | C29: HARV | D29: ERC-20 | E29: 18 | F29: 1e+30 | G29: NO DISPONIBLE: falta la lista oficial de billeteras de tesorería y control interno (ver columnas extra) | H29: 0 | I29: 2026-08-25 (génesis de la 5550; bloque 1 a las 23:40:15 UTC). Despliegue original en la 8532: NO DISPONIBLE | J29: Ninguna en la 5550 (sembrado en el génesis). En la 8532: NO DISPONIBLE | K29: Sin dueño legible por owner(); sin funciones privilegiadas detectadas | L29: 1 | M29: =S29/F29 -> 1 | N29: Ninguna desde el génesis (25-ago-2026). Historial en la 8532: NO DISPONIBLE | O29: No. El repositorio no tiene la fuente Solidity; ver «Huella registrada en ORDENSCAN» | P29: — | Q29: NO DISPONIBLE | R29: NO DISPONIBLE | S29: 1e+30 | T29: 1 | V29: 1e+30 | W29: — | X29: 13 | Y29: 327070a3cb2b28d44930ffceaf30f350f4ccf36f14d6dddca8dafce73c50caf0 | Z29: No | AA29: el símbolo HARV aparece en 15 contratos; bytecode idéntico a otros 13 | AB29: —
A30: 0x716129d8895ea869ac26d321bb1151794b0846e0 | B30: IBS Energy | C30: IBS | D30: ERC-20 | E30: 18 | F30: 500000000 | G30: NO DISPONIBLE: falta la lista oficial de billeteras de tesorería y control interno (ver columnas extra) | H30: 0 | I30: 2026-08-25 (génesis de la 5550; bloque 1 a las 23:40:15 UTC). Despliegue original en la 8532: NO DISPONIBLE | J30: Ninguna en la 5550 (sembrado en el génesis). En la 8532: NO DISPONIBLE | K30: Sin dueño legible por owner(); funciones presentes: mint, burn · quién puede llamarlas: NO DISPONIBLE (sin fuente) | L30: 5 | M30: =S30/F30 -> 1 | N30: Ninguna desde el génesis (25-ago-2026). Historial en la 8532: NO DISPONIBLE | O30: No. El repositorio no tiene la fuente Solidity; ver «Huella registrada en ORDENSCAN» | P30: — | Q30: NO DISPONIBLE | R30: NO DISPONIBLE | S30: 500000000 | T30: 1 | W30: mint, burn | X30: 1 | Y30: 48aeeb7224644fa17eac0da1770ccaca07ab912c703d76ba15c663553c785fa3 | Z30: No | AA30: el símbolo IBS aparece en 2 contratos; bytecode idéntico a otros 1 | AB30: —
A31: 0x7af11d3e94a174f6fc290a5b7791a6dee2718e62 | B31: IBS Energy | C31: IBS | D31: ERC-20 | E31: 18 | F31: 500000000 | G31: NO DISPONIBLE: falta la lista oficial de billeteras de tesorería y control interno (ver columnas extra) | H31: 0 | I31: 2026-08-25 (génesis de la 5550; bloque 1 a las 23:40:15 UTC). Despliegue original en la 8532: NO DISPONIBLE | J31: Ninguna en la 5550 (sembrado en el génesis). En la 8532: NO DISPONIBLE | K31: Sin dueño legible por owner(); funciones presentes: mint, burn · quién puede llamarlas: NO DISPONIBLE (sin fuente) | L31: 4 | M31: =S31/F31 -> 1 | N31: Ninguna desde el génesis (25-ago-2026). Historial en la 8532: NO DISPONIBLE | O31: No. El repositorio no tiene la fuente Solidity; ver «Huella registrada en ORDENSCAN» | P31: — | Q31: NO DISPONIBLE | R31: NO DISPONIBLE | S31: 500000000 | T31: 1 | W31: mint, burn | X31: 1 | Y31: 48aeeb7224644fa17eac0da1770ccaca07ab912c703d76ba15c663553c785fa3 | Z31: Sí | AA31: en el catálogo de ORDENSCAN; el símbolo IBS aparece en 2 contratos; bytecode idéntico a otros 1 | AB31: —
A32: 0x638f2ba0e3e1083d1ba570b449bd266f3860d164 | B32: AMOR GLOBAL | C32: LOVE | D32: ERC-20 | E32: 18 | F32: 77000000 | G32: NO DISPONIBLE: falta la lista oficial de billeteras de tesorería y control interno (ver columnas extra) | H32: 0 | I32: 2026-08-25 (génesis de la 5550; bloque 1 a las 23:40:15 UTC). Despliegue original en la 8532: NO DISPONIBLE | J32: Ninguna en la 5550 (sembrado en el génesis). En la 8532: NO DISPONIBLE | K32: Sin dueño legible por owner(); sin funciones privilegiadas detectadas | L32: 3 | M32: =S32/F32 -> 1 | N32: Ninguna desde el génesis (25-ago-2026). Historial en la 8532: NO DISPONIBLE | O32: No. El repositorio no tiene la fuente Solidity; ver «Huella registrada en ORDENSCAN» | P32: en 2 par(es)/pool(s) AMM | Q32: NO DISPONIBLE | R32: NO DISPONIBLE | S32: 77000000 | T32: 1 | W32: — | X32: 8 | Y32: 29ed4635fa24b53b59a7f91f97ed36923b32907ef0e79c244f6eceaea6eae85c | Z32: Sí | AA32: en el catálogo de ORDENSCAN; bytecode idéntico a otros 8 | AB32: —
A33: 0x18b6680cff71c11067bec312fc48786be2e54ead | B33: MONARKA | C33: MNKA | D33: ERC-20 | E33: 18 | F33: 100000000 | G33: NO DISPONIBLE: falta la lista oficial de billeteras de tesorería y control interno (ver columnas extra) | H33: 0 | I33: 2026-08-25 (génesis de la 5550; bloque 1 a las 23:40:15 UTC). Despliegue original en la 8532: NO DISPONIBLE | J33: Ninguna en la 5550 (sembrado en el génesis). En la 8532: NO DISPONIBLE | K33: Sin dueño legible por owner(); sin funciones privilegiadas detectadas | L33: 5 | M33: =S33/F33 -> 1 | N33: 2026-09-17 23:35 UTC | O33: No. El repositorio no tiene la fuente Solidity; ver «Huella registrada en ORDENSCAN» | P33: en 4 par(es)/pool(s) AMM | Q33: NO DISPONIBLE | R33: NO DISPONIBLE | S33: 100000000 | T33: 1 | W33: — | X33: 8 | Y33: 29ed4635fa24b53b59a7f91f97ed36923b32907ef0e79c244f6eceaea6eae85c | Z33: Sí | AA33: en el catálogo de ORDENSCAN; el símbolo MNKA aparece en 2 contratos; bytecode idéntico a otros 8 | AB33: —
A34: 0x632b7f72a86b39d919fafd5c6d86663caebb49eb | B34: MONARKA | C34: MNKA | D34: ERC-20 | E34: 18 | F34: 1e+26 | G34: NO DISPONIBLE: falta la lista oficial de billeteras de tesorería y control interno (ver columnas extra) | H34: 0 | I34: 2026-08-25 (génesis de la 5550; bloque 1 a las 23:40:15 UTC). Despliegue original en la 8532: NO DISPONIBLE | J34: Ninguna en la 5550 (sembrado en el génesis). En la 8532: NO DISPONIBLE | K34: Sin dueño legible por owner(); sin funciones privilegiadas detectadas | L34: 1 | M34: =S34/F34 -> 1 | N34: Ninguna desde el génesis (25-ago-2026). Historial en la 8532: NO DISPONIBLE | O34: No. El repositorio no tiene la fuente Solidity; ver «Huella registrada en ORDENSCAN» | P34: — | Q34: NO DISPONIBLE | R34: NO DISPONIBLE | S34: 1e+26 | T34: 1 | V34: 1e+26 | W34: — | X34: 13 | Y34: 327070a3cb2b28d44930ffceaf30f350f4ccf36f14d6dddca8dafce73c50caf0 | Z34: No | AA34: el símbolo MNKA aparece en 2 contratos; bytecode idéntico a otros 13 | AB34: —
A35: 0xfb83eea4b384a4b18e5a1eba7a4bb4c0b7ca19c1 | B35: Orden Kapital | C35: ONDK | D35: ERC-20 | E35: 18 | F35: 555000000 | G35: NO DISPONIBLE: falta la lista oficial de billeteras de tesorería y control interno (ver columnas extra) | H35: 0 | I35: 2026-08-25 (génesis de la 5550; bloque 1 a las 23:40:15 UTC). Despliegue original en la 8532: NO DISPONIBLE | J35: Ninguna en la 5550 (sembrado en el génesis). En la 8532: NO DISPONIBLE | K35: Sin dueño legible por owner(); funciones presentes: mint · quién puede llamarlas: NO DISPONIBLE (sin fuente) | L35: 47 con dirección conocida + hasta 88 entradas sin dirección (pueden incluir autorizaciones) | M35: =S35/F35 -> 0.99920424 | N35: 2026-09-17 23:21 UTC | O35: No. El repositorio no tiene la fuente Solidity; ver «Huella registrada en ORDENSCAN» | P35: en 13 par(es)/pool(s) AMM | Q35: NO DISPONIBLE | R35: NO DISPONIBLE | S35: 5.5455835e+08 | T35: 0.99999857 | U35: 792.5 | V35: 79.27 | W35: mint | X35: 3 | Y35: 35cd1e6484dd9d021001e7cf57a3d4bb71a5f894f7089c0b56dcc8b41d870d0d | Z35: Sí | AA35: en el catálogo de ORDENSCAN; bytecode idéntico a otros 3 | AB35: —
A36: 0x92496e1848e001428a3495409a9a9f616bb6dd3b | B36: POLITICAL | C36: POLITICAL | D36: ERC-20 | E36: 18 | F36: 125000000 | G36: NO DISPONIBLE: falta la lista oficial de billeteras de tesorería y control interno (ver columnas extra) | H36: 0 | I36: 2026-08-25 (génesis de la 5550; bloque 1 a las 23:40:15 UTC). Despliegue original en la 8532: NO DISPONIBLE | J36: Ninguna en la 5550 (sembrado en el génesis). En la 8532: NO DISPONIBLE | K36: Sin dueño legible por owner(); sin funciones privilegiadas detectadas | L36: 3 | M36: =S36/F36 -> 1 | N36: Ninguna desde el génesis (25-ago-2026). Historial en la 8532: NO DISPONIBLE | O36: No. El repositorio no tiene la fuente Solidity; ver «Huella registrada en ORDENSCAN» | P36: en 2 par(es)/pool(s) AMM | Q36: NO DISPONIBLE | R36: NO DISPONIBLE | S36: 125000000 | T36: 1 | W36: — | X36: 8 | Y36: 29ed4635fa24b53b59a7f91f97ed36923b32907ef0e79c244f6eceaea6eae85c | Z36: Sí | AA36: en el catálogo de ORDENSCAN; bytecode idéntico a otros 8 | AB36: —
A37: 0x1ac12ebd7739003059d1e9ea2a4863c92d1505dd | B37: REAL STATE | C37: REST | D37: ERC-20 | E37: 18 | F37: 50000000 | G37: NO DISPONIBLE: falta la lista oficial de billeteras de tesorería y control interno (ver columnas extra) | H37: 0 | I37: 2026-08-25 (génesis de la 5550; bloque 1 a las 23:40:15 UTC). Despliegue original en la 8532: NO DISPONIBLE | J37: Ninguna en la 5550 (sembrado en el génesis). En la 8532: NO DISPONIBLE | K37: Sin dueño legible por owner(); sin funciones privilegiadas detectadas | L37: 3 | M37: =S37/F37 -> 1 | N37: Ninguna desde el génesis (25-ago-2026). Historial en la 8532: NO DISPONIBLE | O37: No. El repositorio no tiene la fuente Solidity; ver «Huella registrada en ORDENSCAN» | P37: en 2 par(es)/pool(s) AMM | Q37: NO DISPONIBLE | R37: NO DISPONIBLE | S37: 50000000 | T37: 1 | W37: — | X37: 8 | Y37: 29ed4635fa24b53b59a7f91f97ed36923b32907ef0e79c244f6eceaea6eae85c | Z37: Sí | AA37: en el catálogo de ORDENSCAN; el símbolo REST aparece en 2 contratos; bytecode idéntico a otros 8 | AB37: —
A38: 0x3607163401bc4f9135986c0d3138bff1ebd0cb96 | B38: REAL STATE | C38: REST | D38: ERC-20 | E38: 18 | F38: 1000000000000 | G38: NO DISPONIBLE: falta la lista oficial de billeteras de tesorería y control interno (ver columnas extra) | H38: 0 | I38: 2026-08-25 (génesis de la 5550; bloque 1 a las 23:40:15 UTC). Despliegue original en la 8532: NO DISPONIBLE | J38: Ninguna en la 5550 (sembrado en el génesis). En la 8532: NO DISPONIBLE | K38: Sin dueño legible por owner(); funciones presentes: mint, burn · quién puede llamarlas: NO DISPONIBLE (sin fuente) | L38: 1 | M38: =S38/F38 -> 1 | N38: Ninguna desde el génesis (25-ago-2026). Historial en la 8532: NO DISPONIBLE | O38: No. El repositorio no tiene la fuente Solidity; ver «Huella registrada en ORDENSCAN» | P38: — | Q38: NO DISPONIBLE | R38: NO DISPONIBLE | S38: 1000000000000 | T38: 1 | W38: mint, burn | X38: 2 | Y38: 640abb699107fa0d25a6b0275b82b572aaea2427c7dcdc3ac0c9a745d1320402 | Z38: No | AA38: el símbolo REST aparece en 2 contratos; bytecode idéntico a otros 2 | AB38: —
A39: 0xaac6ae2e2037fc2e94d0b060792e7eb4e5fbfa66 | B39: SOLAR | C39: SOL | D39: ERC-20 | E39: 18 | F39: 21000000 | G39: NO DISPONIBLE: falta la lista oficial de billeteras de tesorería y control interno (ver columnas extra) | H39: 0 | I39: 2026-08-25 (génesis de la 5550; bloque 1 a las 23:40:15 UTC). Despliegue original en la 8532: NO DISPONIBLE | J39: Ninguna en la 5550 (sembrado en el génesis). En la 8532: NO DISPONIBLE | K39: Sin dueño legible por owner(); sin funciones privilegiadas detectadas | L39: 3 | M39: =S39/F39 -> 1 | N39: Ninguna desde el génesis (25-ago-2026). Historial en la 8532: NO DISPONIBLE | O39: No. El repositorio no tiene la fuente Solidity; ver «Huella registrada en ORDENSCAN» | P39: en 2 par(es)/pool(s) AMM | Q39: NO DISPONIBLE | R39: NO DISPONIBLE | S39: 21000000 | T39: 1 | W39: — | X39: 8 | Y39: 29ed4635fa24b53b59a7f91f97ed36923b32907ef0e79c244f6eceaea6eae85c | Z39: Sí | AA39: en el catálogo de ORDENSCAN; bytecode idéntico a otros 8 | AB39: —
A40: 0xc9aff5c20670623021a6afdd6fb3ba765200ad98 | B40: Token 1 | C40: TK1 | D40: ERC-20 | E40: 18 | F40: 0 | G40: NO DISPONIBLE: falta la lista oficial de billeteras de tesorería y control interno (ver columnas extra) | H40: 0 | I40: 2026-08-25 (génesis de la 5550; bloque 1 a las 23:40:15 UTC). Despliegue original en la 8532: NO DISPONIBLE | J40: Ninguna en la 5550 (sembrado en el génesis). En la 8532: NO DISPONIBLE | K40: Sin dueño legible por owner(); sin funciones privilegiadas detectadas | L40: 0 | M40: NO DISPONIBLE | N40: Ninguna desde el génesis (25-ago-2026). Historial en la 8532: NO DISPONIBLE | O40: No. El repositorio no tiene la fuente Solidity; ver «Huella registrada en ORDENSCAN» | P40: — | Q40: NO DISPONIBLE | R40: NO DISPONIBLE | S40: 0 | W40: — | X40: 1 | Y40: 5a412f92161b8b8b6e2fabcde0b067a8f1b6ad2756df2ccb48b7272fe7bb7cee | Z40: No | AA40: el símbolo TK1 aparece en 2 contratos; bytecode idéntico a otros 1 | AB40: —
...

Sheet Tenedores
A1: Token | B1: Contrato | C1: Tenedor | D1: Saldo (unidades) | E1: % del supply | F1: ¿Contrato? | G1: Nota
A2: AGKA | B2: 0x37bcb1c800220e414ed09e044becd3bf9d06ea67 | C2: 0xb710f64d46f9d5f28283bdfee4b13a1e9e9c15af | D2: 100000000 | E2: =D2/INDEX('1.1 Contratos 5550'!F:F,MATCH(B2,'1.1 Contratos 5550'!A:A,0)) -> 1 | F2: No
A3: AGKA | B3: 0x961f798f998c7ff44d47d62c7fa1b572ef187a4b | C3: 0x7ac19672abedf654708fe0be29e978d13c317548 | D3: 499999998 | E3: =D3/INDEX('1.1 Contratos 5550'!F:F,MATCH(B3,'1.1 Contratos 5550'!A:A,0)) -> 1 | F3: No
A4: AGKA | B4: 0x961f798f998c7ff44d47d62c7fa1b572ef187a4b | C4: 0x746268404cc9ca2ef0ac344f02b236db232c3ad8 | D4: 1.8 | E4: =D4/INDEX('1.1 Contratos 5550'!F:F,MATCH(B4,'1.1 Contratos 5550'!A:A,0)) -> 3.6e-09 | F4: No
A5: AGKA | B5: 0x961f798f998c7ff44d47d62c7fa1b572ef187a4b | C5: 0xa624c98b2943c67ac1bc584f3e511cfb5d263ff9 | D5: 0.2 | E5: =D5/INDEX('1.1 Contratos 5550'!F:F,MATCH(B5,'1.1 Contratos 5550'!A:A,0)) -> 4e-10 | F5: No
A6: AGRO | B6: 0x2a31ba919a5339fcb0f8aeeffce2c807b16007fe | C6: 0xb710f64d46f9d5f28283bdfee4b13a1e9e9c15af | D6: 32999998 | E6: =D6/INDEX('1.1 Contratos 5550'!F:F,MATCH(B6,'1.1 Contratos 5550'!A:A,0)) -> 0.99999995 | F6: No
A7: AGRO | B7: 0x2a31ba919a5339fcb0f8aeeffce2c807b16007fe | C7: 0x0d9d6e3256f3ba9a7b1c33d07ca33d83cefea3ff | D7: 1.6 | E7: =D7/INDEX('1.1 Contratos 5550'!F:F,MATCH(B7,'1.1 Contratos 5550'!A:A,0)) -> 4.8484848e-08 | F7: Sí
A8: AGRO | B8: 0x2a31ba919a5339fcb0f8aeeffce2c807b16007fe | C8: 0x4f249b2a104c7eefa1cd0c1e2c3cb9c9c64f0566 | D8: 2e-18 | E8: =D8/INDEX('1.1 Contratos 5550'!F:F,MATCH(B8,'1.1 Contratos 5550'!A:A,0)) -> 6.0606061e-26 | F8: Sí
A9: AIT | B9: 0xae14db486872ac07d74ad69cc09590239b21ba2e | C9: 0xb710f64d46f9d5f28283bdfee4b13a1e9e9c15af | D9: 20999996 | E9: =D9/INDEX('1.1 Contratos 5550'!F:F,MATCH(B9,'1.1 Contratos 5550'!A:A,0)) -> 0.99999981 | F9: No
A10: AIT | B10: 0xae14db486872ac07d74ad69cc09590239b21ba2e | C10: 0x90141ef5f6b453dae06ffbb84e8b13cbdf80ffe6 | D10: 3.77 | E10: =D10/INDEX('1.1 Contratos 5550'!F:F,MATCH(B10,'1.1 Contratos 5550'!A:A,0)) -> 1.7952381e-07 | F10: Sí
A11: AIT | B11: 0xae14db486872ac07d74ad69cc09590239b21ba2e | C11: 0x0186450cd6e7c93c466815facd9e97cadcd0ca1f | D11: 0.23 | E11: =D11/INDEX('1.1 Contratos 5550'!F:F,MATCH(B11,'1.1 Contratos 5550'!A:A,0)) -> 1.0952381e-08 | F11: No
A12: ASL | B12: 0x69846ac960d45f9946c613dfce1b761d37faf098 | C12: 0xb710f64d46f9d5f28283bdfee4b13a1e9e9c15af | D12: 76999991 | E12: =D12/INDEX('1.1 Contratos 5550'!F:F,MATCH(B12,'1.1 Contratos 5550'!A:A,0)) -> 0.99999988 | F12: No
A13: ASL | B13: 0x69846ac960d45f9946c613dfce1b761d37faf098 | C13: 0xef6cbe22d49c6e3007404c99ca96901c89259aed | D13: 8.56 | E13: =D13/INDEX('1.1 Contratos 5550'!F:F,MATCH(B13,'1.1 Contratos 5550'!A:A,0)) -> 1.1116883e-07 | F13: Sí
... A18: AUBEX | B18: 0xf1498640b27a66c0dc505093d70911c060e04fb0 | C18: 0xc55a2a6f9fdc8f7629a438e0ea8077bc2a9a3eaf | D18: 5000 | E18: =D18/INDEX('1.1 Contratos 5550'!F:F,MATCH(B18,'1.1 Contratos 5550'!A:A,0)) -> 5e-05 | F18: No
A19: AUKA | B19: 0x6facc8df79cedc6c5065442ce27e915aa3a26b9b | C19: (sin dirección conocida #1) | D19: 20000000 | E19: =D19/INDEX('1.1 Contratos 5550'!F:F,MATCH(B19,'1.1 Contratos 5550'!A:A,0)) -> 0.36363636 | F19: No | G19: leído por su huella en el almacenamiento; podría ser una autorización y no un saldo
A20: AUKA | B20: 0x6facc8df79cedc6c5065442ce27e915aa3a26b9b | C20: (sin dirección conocida #2) | D20: 20000000 | E20: =D20/INDEX('1.1 Contratos 5550'!F:F,MATCH(B20,'1.1 Contratos 5550'!A:A,0)) -> 0.36363636 | F20: No | G20: leído por su huella en el almacenamiento; podría ser una autorización y no un saldo
A21: AUKA | B21: 0x6facc8df79cedc6c5065442ce27e915aa3a26b9b | C21: 0x3409f79cae2ca2312254ae51708a4380ab38da9e | D21: 14899892 | E21: =D21/INDEX('1.1 Contratos 5550'!F:F,MATCH(B21,'1.1 Contratos 5550'!A:A,0)) -> 0.27090713 | F21: No
A22: AUKA | B22: 0x6facc8df79cedc6c5065442ce27e915aa3a26b9b | C22: 0x746268404cc9ca2ef0ac344f02b236db232c3ad8 | D22: 90013.059 | E22: =D22/INDEX('1.1 Contratos 5550'!F:F,MATCH(B22,'1.1 Contratos 5550'!A:A,0)) -> 0.0016366011 | F22: No
A23: AUKA | B23: 0x6facc8df79cedc6c5065442ce27e915aa3a26b9b | C23: (sin dirección conocida #3) | D23: 100 | E23: =D23/INDEX('1.1 Contratos 5550'!F:F,MATCH(B23,'1.1 Contratos 5550'!A:A,0)) -> 1.8181818e-06 | F23: No | G23: leído por su huella en el almacenamiento; podría ser una autorización y no un saldo
A24: AUKA | B24: 0x6facc8df79cedc6c5065442ce27e915aa3a26b9b | C24: 0xd271f9936ec95f43cccfc0b9fcbe626d547ce239 | D24: 75 | E24: =D24/INDEX('1.1 Contratos 5550'!F:F,MATCH(B24,'1.1 Contratos 5550'!A:A,0)) -> 1.3636364e-06 | F24: No
A25: AUKA | B25: 0x6facc8df79cedc6c5065442ce27e915aa3a26b9b | C25: 0x8979d32c407e22073e258d27adc15b78afc91781 | D25: 45.3 | E25: =D25/INDEX('1.1 Contratos 5550'!F:F,MATCH(B25,'1.1 Contratos 5550'!A:A,0)) -> 8.2363636e-07 | F25: No
A26: AUKA | B26: 0x6facc8df79cedc6c5065442ce27e915aa3a26b9b | C26: 0xd894df2b1eedd017c7bb2b01d9a16391ccc4bda5 | D26: 30 | E26: =D26/INDEX('1.1 Contratos 5550'!F:F,MATCH(B26,'1.1 Contratos 5550'!A:A,0)) -> 5.4545455e-07 | F26: No
A27: AUKA | B27: 0x6facc8df79cedc6c5065442ce27e915aa3a26b9b | C27: 0xd3790bfd26fd215491e68180f1e2da2c3b8d973d | D27: 9.3892676 | E27: =D27/INDEX('1.1 Contratos 5550'!F:F,MATCH(B27,'1.1 Contratos 5550'!A:A,0)) -> 1.7071396e-07 | F27: Sí
A28: AUKA | B28: 0x6facc8df79cedc6c5065442ce27e915aa3a26b9b | C28: 0x8e839af7a405f49bf72b239929b8ee3c07ee7ba0 | D28: 2.5996 | E28: =D28/INDEX('1.1 Contratos 5550'!F:F,MATCH(B28,'1.1 Contratos 5550'!A:A,0)) -> 4.7265455e-08 | F28: No
A29: AUKA | B29: 0x6facc8df79cedc6c5065442ce27e915aa3a26b9b | C29: (sin dirección conocida #4) | D29: 2 | E29: =D29/INDEX('1.1 Contratos 5550'!F:F,MATCH(B29,'1.1 Contratos 5550'!A:A,0)) -> 3.6363636e-08 | F29: No | G29: leído por su huella en el almacenamiento; podría ser una autorización y no un saldo
A30: AUKA | B30: 0x6facc8df79cedc6c5065442ce27e915aa3a26b9b | C30: 0x95bbab35cab7606979c50caa36e2bd8f708f4ce0 | D30: 2 | E30: =D30/INDEX('1.1 Contratos 5550'!F:F,MATCH(B30,'1.1 Contratos 5550'!A:A,0)) -> 3.6363636e-08 | F30: Sí
A31: AUKA | B31: 0x6facc8df79cedc6c5065442ce27e915aa3a26b9b | C31: 0xd747977c98ce35007beadf88037bbe5bc71cca3f | D31: 1 | E31: =D31/INDEX('1.1 Contratos 5550'!F:F,MATCH(B31,'1.1 Contratos 5550'!A:A,0)) -> 1.8181818e-08 | F31: No
A32: AUKA | B32: 0x6facc8df79cedc6c5065442ce27e915aa3a26b9b | C32: (sin dirección conocida #5) | D32: 1 | E32: =D32/INDEX('1.1 Contratos 5550'!F:F,MATCH(B32,'1.1 Contratos 5550'!A:A,0)) -> 1.8181818e-08 | F32: No | G32: leído por su huella en el almacenamiento; podría ser una autorización y no un saldo
A33: AUKA | B33: 0x6facc8df79cedc6c5065442ce27e915aa3a26b9b | C33: 0x22ee4e32c9a01d9db891763387f1f6d6cca832d3 | D33: 0.99996 | E33: =D33/INDEX('1.1 Contratos 5550'!F:F,MATCH(B33,'1.1 Contratos 5550'!A:A,0)) -> 1.8181091e-08 | F33: No
A34: AUKA | B34: 0x6facc8df79cedc6c5065442ce27e915aa3a26b9b | C34: 0x0186450cd6e7c93c466815facd9e97cadcd0ca1f | D34: 0.85321117 | E34: =D34/INDEX('1.1 Contratos 5550'!F:F,MATCH(B34,'1.1 Contratos 5550'!A:A,0)) -> 1.551293e-08 | F34: No
A35: AUKA | B35: 0x6facc8df79cedc6c5065442ce27e915aa3a26b9b | C35: 0x3063a26b5f7efb2dbb96637514650dd64de80ac0 | D35: 0.75748124 | E35: =D35/INDEX('1.1 Contratos 5550'!F:F,MATCH(B35,'1.1 Contratos 5550'!A:A,0)) -> 1.3772386e-08 | F35: No
A36: AUKA | B36: 0x6facc8df79cedc6c5065442ce27e915aa3a26b9b | C36: 0x4a82cc10f6075cfda1bc02b48458eccf56b92154 | D36: 0.35 | E36: =D36/INDEX('1.1 Contratos 5550'!F:F,MATCH(B36,'1.1 Contratos 5550'!A:A,0)) -> 6.3636364e-09 | F36: No
A37: AUKA | B37: 0x6facc8df79cedc6c5065442ce27e915aa3a26b9b | C37: (sin dirección conocida #6) | D37: 0.135 | E37: =D37/INDEX('1.1 Contratos 5550'!F:F,MATCH(B37,'1.1 Contratos 5550'!A:A,0)) -> 2.4545455e-09 | F37: No | G37: leído por su huella en el almacenamiento; podría ser una autorización y no un saldo
A38: AUKA | B38: 0x6facc8df79cedc6c5065442ce27e915aa3a26b9b | C38: 0xb3244d79725c7e603992244c61d5d874cbf2e65d | D38: 0.1177 | E38: =D38/INDEX('1.1 Contratos 5550'!F:F,MATCH(B38,'1.1 Contratos 5550'!A:A,0)) -> 2.14e-09 | F38: No
A39: AUKA | B39: 0x6facc8df79cedc6c5065442ce27e915aa3a26b9b | C39: 0x5b46e429b56d204eafa7b27a775d8f165af63d26 | D39: 0.067 | E39: =D39/INDEX('1.1 Contratos 5550'!F:F,MATCH(B39,'1.1 Contratos 5550'!A:A,0)) -> 1.2181818e-09 | F39: No
A40: AUKA | B40: 0x6facc8df79cedc6c5065442ce27e915aa3a26b9b | C40: 0x25d30337d2df2c70d221961700692548f7c34aa7 | D40: 0.042 | E40: =D40/INDEX('1.1 Contratos 5550'!F:F,MATCH(B40,'1.1 Contratos 5550'!A:A,0)) -> 7.6363636e-10 | F40: No
A41: AUKA | B41: 0x6facc8df79cedc6c5065442ce27e915aa3a26b9b | C41: 0xf31b5d5fd72af5b3d51683fd041e5d1485257a78 | D41: 0.032 | E41: =D41/INDEX('1.1 Contratos 5550'!F:F,MATCH(B41,'1.1 Contratos 5550'!A:A,0)) -> 5.8181818e-10 | F41: No
A42: AUKA | B42: 0x6facc8df79cedc6c5065442ce27e915aa3a26b9b | C42: 0xcc60f21f5e40515301f62c415618e284ebcfdf19 | D42: 0.032 | E42: =D42/INDEX('1.1 Contratos 5550'!F:F,MATCH(B42,'1.1 Contratos 5550'!A:A,0)) -> 5.8181818e-10 | F42: No
A43: AUKA | B43: 0x6facc8df79cedc6c5065442ce27e915aa3a26b9b | C43: 0xc29832d386497bc662f1d8768328d2e07510981a | D43: 0.032 | E43: =D43/INDEX('1.1 Contratos 5550'!F:F,MATCH(B43,'1.1 Contratos 5550'!A:A,0)) -> 5.8181818e-10 | F43: No
A44: AUKA | B44: 0x6facc8df79cedc6c5065442ce27e915aa3a26b9b | C44: 0xb3ba774a3db667c4e3257a403c71ac4aeced251b | D44: 0.032 | E44: =D44/INDEX('1.1 Contratos 5550'!F:F,MATCH(B44,'1.1 Contratos 5550'!A:A,0)) -> 5.8181818e-10 | F44: No
...

Sheet 1.2 Contratos 8532
A1: Dirección del contrato (8532) | B1: Nombre | C1: Símbolo | D1: Estándar | E1: Decimales | F1: Supply total | G1: Supply circulante | H1: Bloque de despliegue | I1: Fecha de despliegue | J1: Cuenta desplegadora | K1: Roles privilegiados | L1: Número de tenedores | M1: Concentración | N1: Última transferencia | O1: Código verificado | P1: Contratos relacionados | Q1: Responsable interno | R1: Origen | S1: Estado respecto de la migración | T1: Dirección en la 5550 | U1: Saldo nativo al corte (ORIGEN) | V1: Cómo se identificó la dirección
A2: 0x04e794006db49ed6cf6942ac2ba512fda113fcd3 | B2: TokenB | C2: TKNB | D2: ERC-20 | E2: 18 | F2: Ver hoja 1.1 (mismo código y almacenamiento; puede diferir por transacciones posteriores al corte) | G2: Ver hoja 1.1 (mismo código y almacenamiento; puede diferir por transacciones posteriores al corte) | H2: NO DISPONIBLE | I2: NO DISPONIBLE | J2: NO DISPONIBLE | K2: Ver hoja 1.1 (mismo código y almacenamiento; puede diferir por transacciones posteriores al corte) | L2: Ver hoja 1.1 (mismo código y almacenamiento; puede diferir por transacciones posteriores al corte) | M2: Ver hoja 1.1 (mismo código y almacenamiento; puede diferir por transacciones posteriores al corte) | N2: NO DISPONIBLE | O2: No (sin fuente en el repositorio) | P2: Ver hoja 1.1 (mismo código y almacenamiento; puede diferir por transacciones posteriores al corte) | Q2: NO DISPONIBLE | R2: NO DISPONIBLE | S2: Migrado (misma dirección, código y almacenamiento copiados al génesis de la 5550) | T2: 0x04e794006db49ed6cf6942ac2ba512fda113fcd3 | U2: 0 | V2: volcado del estado
A3: 0x062be19ed343e24ba4e22ef9c1f5563559b85224 | B3: Wrapped Origen | C3: WETH | D3: Otro | E3: 18 | F3: Ver hoja 1.1 (mismo código y almacenamiento; puede diferir por transacciones posteriores al corte) | G3: Ver hoja 1.1 (mismo código y almacenamiento; puede diferir por transacciones posteriores al corte) | H3: NO DISPONIBLE | I3: NO DISPONIBLE | J3: NO DISPONIBLE | K3: Ver hoja 1.1 (mismo código y almacenamiento; puede diferir por transacciones posteriores al corte) | L3: Ver hoja 1.1 (mismo código y almacenamiento; puede diferir por transacciones posteriores al corte) | M3: Ver hoja 1.1 (mismo código y almacenamiento; puede diferir por transacciones posteriores al corte) | N3: NO DISPONIBLE | O3: No (sin fuente en el repositorio) | P3: Ver hoja 1.1 (mismo código y almacenamiento; puede diferir por transacciones posteriores al corte) | Q3: NO DISPONIBLE | R3: NO DISPONIBLE | S3: Migrado (misma dirección, código y almacenamiento copiados al génesis de la 5550) | T3: 0x062be19ed343e24ba4e22ef9c1f5563559b85224 | U3: 0 | V3: volcado del estado
A4: 0x0a16b1bc547b1ec1cb6b82d4f0cb1df07f7d3500 | B4: NO DISPONIBLE | C4: NO DISPONIBLE | D4: Factoría AMM | E4: NO DISPONIBLE | F4: Ver hoja 1.1 (mismo código y almacenamiento; puede diferir por transacciones posteriores al corte) | G4: Ver hoja 1.1 (mismo código y almacenamiento; puede diferir por transacciones posteriores al corte) | H4: NO DISPONIBLE | I4: NO DISPONIBLE | J4: NO DISPONIBLE | K4: Ver hoja 1.1 (mismo código y almacenamiento; puede diferir por transacciones posteriores al corte) | L4: Ver hoja 1.1 (mismo código y almacenamiento; puede diferir por transacciones posteriores al corte) | M4: Ver hoja 1.1 (mismo código y almacenamiento; puede diferir por transacciones posteriores al corte) | N4: NO DISPONIBLE | O4: No (sin fuente en el repositorio) | P4: Ver hoja 1.1 (mismo código y almacenamiento; puede diferir por transacciones posteriores al corte) | Q4: NO DISPONIBLE | R4: NO DISPONIBLE | S4: Migrado (misma dirección, código y almacenamiento copiados al génesis de la 5550) | T4: 0x0a16b1bc547b1ec1cb6b82d4f0cb1df07f7d3500 | U4: 0 | V4: volcado del estado
A5: 0x0d9d6e3256f3ba9a7b1c33d07ca33d83cefea3ff | B5: NO DISPONIBLE | C5: NO DISPONIBLE | D5: Pool AMM V3 | E5: NO DISPONIBLE | F5: Ver hoja 1.1 (mismo código y almacenamiento; puede diferir por transacciones posteriores al corte) | G5: Ver hoja 1.1 (mismo código y almacenamiento; puede diferir por transacciones posteriores al corte) | H5: NO DISPONIBLE | I5: NO DISPONIBLE | J5: NO DISPONIBLE | K5: Ver hoja 1.1 (mismo código y almacenamiento; puede diferir por transacciones posteriores al corte) | L5: Ver hoja 1.1 (mismo código y almacenamiento; puede diferir por transacciones posteriores al corte) | M5: Ver hoja 1.1 (mismo código y almacenamiento; puede diferir por transacciones posteriores al corte) | N5: NO DISPONIBLE | O5: No (sin fuente en el repositorio) | P5: Ver hoja 1.1 (mismo código y almacenamiento; puede diferir por transacciones posteriores al corte) | Q5: NO DISPONIBLE | R5: NO DISPONIBLE | S5: Migrado (misma dirección, código y almacenamiento copiados al génesis de la 5550) | T5: 0x0d9d6e3256f3ba9a7b1c33d07ca33d83cefea3ff | U5: 0 | V5: volcado del estado
A6: 0x0fa04d11f28b28cbc9b98dd016f02023addb1923 | B6: Harvi | C6: HARV | D6: ERC-20 | E6: 18 | F6: Ver hoja 1.1 (mismo código y almacenamiento; puede diferir por transacciones posteriores al corte) | G6: Ver hoja 1.1 (mismo código y almacenamiento; puede diferir por transacciones posteriores al corte) | H6: NO DISPONIBLE | I6: NO DISPONIBLE | J6: NO DISPONIBLE | K6: Ver hoja 1.1 (mismo código y almacenamiento; puede diferir por transacciones posteriores al corte) | L6: Ver hoja 1.1 (mismo código y almacenamiento; puede diferir por transacciones posteriores al corte) | M6: Ver hoja 1.1 (mismo código y almacenamiento; puede diferir por transacciones posteriores al corte) | N6: NO DISPONIBLE | O6: No (sin fuente en el repositorio) | P6: Ver hoja 1.1 (mismo código y almacenamiento; puede diferir por transacciones posteriores al corte) | Q6: NO DISPONIBLE | R6: NO DISPONIBLE | S6: Migrado (misma dirección, código y almacenamiento copiados al génesis de la 5550) | T6: 0x0fa04d11f28b28cbc9b98dd016f02023addb1923 | U6: 0 | V6: volcado del estado
A7: 0x0fbad77bd66383ee303a2e56a73d8cfd42dc36db | B7: NO DISPONIBLE | C7: NO DISPONIBLE | D7: Otro | E7: NO DISPONIBLE | F7: Ver hoja 1.1 (mismo código y almacenamiento; puede diferir por transacciones posteriores al corte) | G7: Ver hoja 1.1 (mismo código y almacenamiento; puede diferir por transacciones posteriores al corte) | H7: NO DISPONIBLE | I7: NO DISPONIBLE | J7: NO DISPONIBLE | K7: Ver hoja 1.1 (mismo código y almacenamiento; puede diferir por transacciones posteriores al corte) | L7: Ver hoja 1.1 (mismo código y almacenamiento; puede diferir por transacciones posteriores al corte) | M7: Ver hoja 1.1 (mismo código y almacenamiento; puede diferir por transacciones posteriores al corte) | N7: NO DISPONIBLE | O7: No (sin fuente en el repositorio) | P7: Ver hoja 1.1 (mismo código y almacenamiento; puede diferir por transacciones posteriores al corte) | Q7: NO DISPONIBLE | R7: NO DISPONIBLE | S7: Migrado (misma dirección, código y almacenamiento copiados al génesis de la 5550) | T7: 0x0fbad77bd66383ee303a2e56a73d8cfd42dc36db | U7: 0 | V7: volcado del estado
A8: 0x14c27762b115cb4e6d4c8fec69577590795db3b0 | B8: HARVI | C8: HARV | D8: ERC-20 | E8: 18 | F8: Ver hoja 1.1 (mismo código y almacenamiento; puede diferir por transacciones posteriores al corte) | G8: Ver hoja 1.1 (mismo código y almacenamiento; puede diferir por transacciones posteriores al corte) | H8: NO DISPONIBLE | I8: NO DISPONIBLE | J8: NO DISPONIBLE | K8: Ver hoja 1.1 (mismo código y almacenamiento; puede diferir por transacciones posteriores al corte) | L8: Ver hoja 1.1 (mismo código y almacenamiento; puede diferir por transacciones posteriores al corte) | M8: Ver hoja 1.1 (mismo código y almacenamiento; puede diferir por transacciones posteriores al corte) | N8: NO DISPONIBLE | O8: No (sin fuente en el repositorio) | P8: Ver hoja 1.1 (mismo código y almacenamiento; puede diferir por transacciones posteriores al corte) | Q8: NO DISPONIBLE | R8: NO DISPONIBLE | S8: Migrado (misma dirección, código y almacenamiento copiados al génesis de la 5550) | T8: 0x14c27762b115cb4e6d4c8fec69577590795db3b0 | U8: 0 | V8: volcado del estado
